<?xml version="1.0"?>

<robot name="quadrotor" xmlns:xacro="http://www.ros.org/wiki/xacro">
   
    <xacro:property name="M_PI" value="3.1415926535897931" />
    
    <!-- Included URDF Files -->
    <xacro:include filename="$(find hector_quadrotor_description)/urdf/quadrotor_base.urdf.xacro" />
    
    <!-- Instantiate quadrotor_base_macro once (has no parameters atm) -->
    <xacro:quadrotor_base_macro />

    <!-- add box -->
    <joint name="$base_box_joint" type="floating">
        <origin rpy="0 0 0" xyz="1 0 0.1"/>
        <parent link="base_link"/>
        <child link="box_link"/>
    </joint>

    <link name="box_link">

        <visual>
            <origin xyz="0 0 0" rpy="0 0 0" />
            <geometry>
                <box size=".2 .2 .1" />
            </geometry>
            <material name="Orange">
                <color rgba="${255/255} ${108/255} ${10/255} 1.0"/>
            </material>
        </visual>

        <collision>
            <origin xyz="0 0 0" rpy="0 0 0" />
            <geometry>
                <box size=".2 .2 .1" />
            </geometry>
        </collision>

        <inertial>
            <mass value="0.1" />
            <origin xyz="0 0 0" rpy="0 0 0" />
            <inertia ixx="0.0004167" ixy="0" ixz="0" iyy="0.0004167" iyz="0" izz="0.0006667" />
        </inertial>

    </link>

</robot>

